Command "python setup.py egg_info" failed with error code 1 in /tmp/pip-build-7KHXaG/psycopg2/

install anaconda
bash Anaconda2-4.1.1-Linux-x86_64.sh

clone NILMTK
cd ~
git clone https://github.com/nilmtk/nilmtk.git
cd nilmtk

install conda environment
conda install -c conda conda-env

The following packages will be SUPERCEDED by a higher-priority channel:

    conda-env:   2.5.1-py27_0  --> 1.4.1-py27_0_gd8a6659 conda

The following packages will be DOWNGRADED due to dependency conflicts:

    conda:       4.1.6-py27_0  --> 4.0.11-py27_0              
    conda-build: 1.21.3-py27_0 --> 1.20.3-py27_0 

install once again (because conda env create cannot find pyhton 2.7)
The following packages will be UPDATED:

    conda:     4.0.11-py27_0         --> 4.1.9-py27_0
    conda-env: 1.4.1-py27_0_gd8a6659 --> 2.5.2-py27_0



# install conda for NILMTK
conda env create
source activate nilmtk-env

install nilm_metadata
cd ~
git clone https://github.com/nilmtk/nilm_metadata/
cd nilm_metadata; python setup.py develop; cd ..

error => yaml.h no such file or directory 
pip uninstall pyyaml
apt-get install libyaml-dev libpython2.7-dev
pip install pyyaml

install nilmtk
cd ~/nilmtk
python setup.py develop

unit test
nosetests

ERROR FHMM disaggregation
ValueError: invalid combinate of [values_axes] on appending data [name->values_block_0,cname->values_block_0,dtype->float64,kind->float,shape->(1, 1878)] vs current table [name->values_block_0,cname->values_block_0,dtype->float32,kind->float,shape->None]

# rizky's probles, downgrade -> pip's problem, this package should be installed
sudo apt-get install libpq-dev python-dev

After downgrade to 0.17.1
IndexError: only integers, slices (`:`), ellipsis (`...`), numpy.newaxis (`None`) and integer or boolean arrays are valid indices

# eco convert ERROR
Building 4 , Meter no. 10 => Done for  2013-01-23
Computing for folder  08
Traceback (most recent call last):
  File "<stdin>", line 1, in <module>
  File "nilmtk/dataset_converters/eco/convert_eco.py", line 125, in convert_eco
    df.index = pd.DatetimeIndex(start=fi[:-4], freq='s', periods=86400, tz = 'GMT')
  File "/home/airawan/anaconda2/envs/nilmtk-env/lib/python2.7/site-packages/pandas/util/decorators.py", line 88, in wrapper
    return func(*args, **kwargs)
  File "/home/airawan/anaconda2/envs/nilmtk-env/lib/python2.7/site-packages/pandas/tseries/index.py", line 226, in __new__
    ambiguous=ambiguous)
  File "/home/airawan/anaconda2/envs/nilmtk-env/lib/python2.7/site-packages/pandas/tseries/index.py", line 354, in _generate
    start = Timestamp(start)
  File "pandas/tslib.pyx", line 278, in pandas.tslib.Timestamp.__new__ (pandas/tslib.c:7835)
  File "pandas/tslib.pyx", line 1114, in pandas.tslib.convert_to_tsobject (pandas/tslib.c:21247)
ValueError
>>> 

